<?xml version="1.0" encoding="utf-8"?>
<!-- This URDF was automatically created by SolidWorks to URDF Exporter! Originally created by Stephen Brawner (brawner@gmail.com) 
     Commit Version: 1.6.0-1-g15f4949  Build Version: 1.6.7594.29634
     For more information, please see http://wiki.ros.org/sw_urdf_exporter -->
<robot
  name="rover_autonav">
  <link
    name="base_link">
    <inertial>
      <origin
        xyz="-2.2204E-16 3.8858E-16 -0.10299"
        rpy="0 0 0" />
      <mass
        value="67.568" />
      <inertia
        ixx="1.2576"
        ixy="-8.9345E-15"
        ixz="1.1652E-14"
        iyy="3.7875"
        iyz="-2.6748E-15"
        izz="4.548" />
    </inertial>
    <visual>
      <origin
        xyz="0 0 0"
        rpy="0 0 0" />
      <geometry>
        <mesh
          filename="package://rover_autonav/meshes/base_link.STL" />
      </geometry>
      <material
        name="">
        <color
          rgba="0.79216 0.81961 0.93333 1" />
      </material>
    </visual>
    <collision>
      <origin
        xyz="0 0 0"
        rpy="0 0 0" />
      <geometry>
        <mesh
          filename="package://rover_autonav/meshes/base_link.STL" />
      </geometry>
    </collision>
  </link>

 <link name="dummy">
	</link> 
 <joint name="dummy_joint" type="fixed">
    <parent link="dummy"/>
    <child link="base_link"/>
  </joint>

<joint name="hokuyo_joint" type="fixed">
    <axis xyz="0 1 0" />
    <origin xyz="0.35 0 0.02" rpy="0 0 0"/>
    <parent link="base_link"/>
    <child link="hokuyo_link"/>
  </joint>

  <!-- Hokuyo Laser -->
  <link name="hokuyo_link">
    <collision>
      <origin xyz="0 0 0.05" rpy="0 0 0"/>
      <geometry>
    <box size="0.1 0.1 0.1"/>
      </geometry>
    </collision>

    <visual>
      <origin xyz="0 0 0" rpy="0 0 0"/>
      <geometry>
        <mesh filename="package://rover_control/meshes/hokuyo.dae"/>
      </geometry>
    </visual>

    <inertial>
      <mass value="1e-5" />
      <origin xyz="0 0 0" rpy="0 0 0"/>
      <inertia ixx="1e-6" ixy="0" ixz="0" iyy="1e-6" iyz="0" izz="1e-6" />
    </inertial>
  </link>
  <gazebo reference="hokuyo_link">
    <material>Gazebo/Grey</material>
  </gazebo>

 <joint name="camera_joint" type="fixed">
    <axis xyz="0 1 0" />
    <origin xyz="0.25 0.1 0.1" rpy="0 0 0"/>
    <parent link="base_link"/>
    <child link="camera_link"/>
  </joint>

  <!-- Camera -->
  <link name="camera_link">
    <collision>
      <origin xyz="0 0 0" rpy="0 0 0"/>
      <geometry>
    <box size="0.05 0.05 0.05"/>
      </geometry>
    </collision>

    <visual>
      <origin xyz="0 0 0" rpy="0 0 0"/>
      <geometry>
    <box size="0.1 0.1 0.1"/>
      </geometry>
      <material name="red"/>
    </visual>

    <inertial>
      <mass value="1e-5" />
      <origin xyz="0 0 0" rpy="0 0 0"/>
      <inertia ixx="1e-6" ixy="0" ixz="0" iyy="1e-6" iyz="0" izz="1e-6" />
    </inertial>
  </link>
  <gazebo reference="camera_link">
    <material>Gazebo/Blue</material>
  </gazebo>
  <link
    name="lbacklink">
    <inertial>
      <origin
        xyz="-7.27733231620231E-07 0.05842 1.62491302746481E-06"
        rpy="0 0 0" />
         <mass
        value="5.6739801254924" />
      <inertia
        ixx="0.0284379209888981"
        ixy="-5.75264381966658E-17"
        ixz="-3.92244964079017E-09"
        iyy="0.0446580879636162"
        iyz="5.59109627307512E-17"
        izz="0.0284379279903993" />
    </inertial>
    <visual>
      <origin
        xyz="0 0 0"
        rpy="0 0 0" />
      <geometry>
        <mesh
          filename="package://rover_autonav/meshes/lbacklink.STL" />
      </geometry>
      <material
        name="">
        <color
          rgba="0.792156862745098 0.819607843137255 0.933333333333333 1" />
      </material>
    </visual>
    <collision>
      <origin
        xyz="0 0 0"
        rpy="0 0 0" />
      <geometry>
        <mesh
          filename="package://rover_autonav/meshes/lbacklink.STL" />
      </geometry>
    </collision>
  </link>
  <gazebo reference="lbacklink">
    <kp>1000000.0</kp> <!-- kp and kd for rubber -->
    <kd>100.0</kd>
    <mu1>1.0</mu1>
    <mu2>1.0</mu2>
    <maxVel>1.0</maxVel>
    <minDepth>0.00</minDepth>
    <material>Gazebo/Black</material>
  </gazebo>
  <joint
    name="backleft"
    type="continuous">
    <origin
      xyz="-0.38078 -0.35179 -0.31801"
      rpy="0 0 0" />
    <parent
      link="base_link" />
    <child
      link="lbacklink" />
    <axis
      xyz="0 1 0" />
    <limit
      effort="1000000"
      velocity="1000000" />
  </joint>
  <link
    name="rbacklink">
    <inertial>
      <origin
        xyz="5.02792962708831E-07 -0.05842 -1.70796289178377E-06"
        rpy="0 0 0" />
      <mass
        value="5.6739801254924" />
      <inertia
        ixx="0.0284379200707492"
        ixy="-5.63682702496539E-17"
        ixz="-2.84854228166472E-09"
        iyy="0.0446580879636162"
        iyz="5.62895689764963E-17"
        izz="0.0284379289085482" />
    </inertial>
    <visual>
      <origin
        xyz="0 0 0"
        rpy="0 0 0" />
      <geometry>
        <mesh
          filename="package://rover_autonav/meshes/rbacklink.STL" />
      </geometry>
      <material
        name="">
        <color
          rgba="0.792156862745098 0.819607843137255 0.933333333333333 1" />
      </material>
    </visual>
    <collision>
      <origin
        xyz="0 0 0"
        rpy="0 0 0" />
      <geometry>
        <mesh
          filename="package://rover_autonav/meshes/rbacklink.STL" />
      </geometry>
    </collision>
  </link>
  <gazebo reference="rbacklink">
  <kp>1000000.0</kp> <!-- kp and kd for rubber -->
    <kd>100.0</kd>
    <mu1>1.0</mu1>
    <mu2>1.0</mu2>
    <maxVel>1.0</maxVel>
    <minDepth>0.00</minDepth>
    <material>Gazebo/Black</material>
  </gazebo>
  <joint
    name="backright"
    type="continuous">
    <origin
      xyz="-0.38115 0.35179 -0.31701"
      rpy="0 0 0" />
    <parent
      link="base_link" />
    <child
      link="rbacklink" />
    <axis
      xyz="0 1 0" />
    <limit
      effort="1000000"
      velocity="1000000" />
  </joint>
  <link
    name="lfrontlink">
    <inertial>
      <origin
        xyz="7.29369893370801E-08 0.05842 1.77893737907109E-06"
        rpy="0 0 0" />
    <mass
        value="5.6739801254924" />
      <inertia
        ixx="0.0284379192498368"
        ixy="-5.69933931600498E-17"
        ixz="4.30391359396819E-10"
        iyy="0.0446580879636162"
        iyz="5.89209747200998E-17"
        izz="0.0284379297294607" />
    </inertial>
    <visual>
      <origin
        xyz="0 0 0"
        rpy="0 0 0" />
      <geometry>
        <mesh
          filename="package://rover_autonav/meshes/lfrontlink.STL" />
      </geometry>
      <material
        name="">
        <color
          rgba="0.792156862745098 0.819607843137255 0.933333333333333 1" />
      </material>
    </visual>
    <collision>
      <origin
        xyz="0 0 0"
        rpy="0 0 0" />
      <geometry>
        <mesh
          filename="package://rover_autonav/meshes/lfrontlink.STL" />
      </geometry>
    </collision>
  </link>
  <gazebo reference="lfrontlink">
    <kp>1000000.0</kp> <!-- kp and kd for rubber -->
    <kd>100.0</kd>
    <mu1>1.0</mu1>
    <mu2>1.0</mu2>
    <maxVel>1.0</maxVel>
    <minDepth>0.00</minDepth>
    <material>Gazebo/Grey</material>
  </gazebo>
  <joint
    name="frontleft"
    type="continuous">
    <origin
      xyz="0.38098 -0.35179 -0.31805"
      rpy="0 0 0" />
    <parent
      link="base_link" />
    <child
      link="lfrontlink" />
    <axis
      xyz="0 1 0" />
    <limit
      effort="1000000"
      velocity="1000000" />
  </joint>
  <link
    name="rfrontlink">
    <inertial>
      <origin
        xyz="-1.66413693092338E-06 -0.0584199999999999 -6.32918855159037E-07"
        rpy="0 0 0" />
    <mass
        value="5.6739801254924" />
      <inertia
        ixx="0.0284379192498368"
        ixy="-5.69933931600498E-17"
        ixz="4.30391359396819E-10"
        iyy="0.0446580879636162"
        iyz="5.89209747200998E-17"
        izz="0.0284379297294607" />
    </inertial>
    <visual>
      <origin
        xyz="0 0 0"
        rpy="0 0 0" />
      <geometry>
        <mesh
          filename="package://rover_autonav/meshes/rfrontlink.STL" />
      </geometry>
      <material
        name="">
        <color
          rgba="0.792156862745098 0.819607843137255 0.933333333333333 1" />
      </material>
    </visual>
    <collision>
      <origin
        xyz="0 0 0"
        rpy="0 0 0" />
      <geometry>
        <mesh
          filename="package://rover_autonav/meshes/rfrontlink.STL" />
      </geometry>
    </collision>
  </link>
  <gazebo reference="rfrontlink">
    <kp>1000000.0</kp> <!-- kp and kd for rubber -->
    <kd>100.0</kd>
    <mu1>1.0</mu1>
    <mu2>1.0</mu2>
    <maxVel>1.0</maxVel>
    <minDepth>0.00</minDepth>
    <material>Gazebo/Grey</material>
  </gazebo>
  <joint
    name="frontright"
    type="continuous">
    <origin
      xyz="0.3815 0.35179 -0.31733"
      rpy="0 0 0" />
    <parent
      link="base_link" />
    <child
      link="rfrontlink" />
    <axis
      xyz="0 1 0" />
    <limit
      effort="1000000"
      velocity="1000000" />
  </joint>
<gazebo reference="camera_link">
  <sensor name="kinect_camera" type="depth">
    <update_rate>20</update_rate>
    <camera>
      <horizontal_fov>1.047198</horizontal_fov>
      <image>
        <width>640</width>
        <height>480</height>
        <format>R8G8B8</format>
      </image>
      <clip>
        <near>0.05</near>
        <far>3</far>
      </clip>
    </camera>
    <plugin name="camera_link_controller" filename="libgazebo_ros_openni_kinect.so">
      <baseline>0.2</baseline>
      <alwaysOn>true</alwaysOn>
      <updateRate>1.0</updateRate>
      <cameraName>camera_link_ir</cameraName>
      <imageTopicName>/camera_link/color/image_raw</imageTopicName>
      <cameraInfoTopicName>/camera_link/color/camera_info</cameraInfoTopicName>
      <depthImageTopicName>/camera_link/depth/image_raw</depthImageTopicName>
      <depthImageInfoTopicName>/camera_link/depth/camera_info</depthImageInfoTopicName>
      <pointCloudTopicName>/camera_link/depth/points</pointCloudTopicName>
      <frameName>camera_link</frameName>
      <pointCloudCutoff>0.5</pointCloudCutoff>
      <pointCloudCutoffMax>3.0</pointCloudCutoffMax>
      <distortionK1>0.00000001</distortionK1>
      <distortionK2>0.00000001</distortionK2>
      <distortionK3>0.00000001</distortionK3>
      <distortionT1>0.00000001</distortionT1>
      <distortionT2>0.00000001</distortionT2>
      <CxPrime>0</CxPrime>
      <Cx>0</Cx>
      <Cy>0</Cy>
      <focalLength>0</focalLength>
      <hackBaseline>0</hackBaseline>
    </plugin>
  </sensor>
</gazebo>

 <!-- hokuyo -->
  <gazebo reference="hokuyo_link">
    <sensor type="ray" name="head_hokuyo_sensor">
      <pose>0 0 0 0 0 0</pose>
      <visualize>true</visualize>
      <update_rate>100</update_rate>
      <ray>
        <scan>
          <horizontal>
            <samples>360</samples>
            <resolution>1</resolution>
            <min_angle>-1.57</min_angle>
            <max_angle>1.57</max_angle>
          </horizontal>
        </scan>
        <range>
          <min>0.10</min>
          <max>20</max>
          <resolution>0.01</resolution>
        </range>
        <noise>
          <type>gaussian</type>
          <!-- Noise parameters based on published spec for Hokuyo laser
               achieving "+-30mm" accuracy at range < 10m.  A mean of 0.0m and
               stddev of 0.01m will put 99.7% of samples within 0.03m of the true
               reading. -->
          <mean>0.0</mean>
          <stddev>0.01</stddev>
        </noise>
      </ray>
      <plugin name="gazebo_ros_head_hokuyo_controller" filename="libgazebo_ros_laser.so">
        <topicName>/scan</topicName>
        <frameName>hokuyo_link</frameName>
      </plugin>
    </sensor>
  </gazebo>
	<gazebo>
	  <plugin name="skid_steer_drive_controller" filename="libgazebo_ros_skid_steer_drive.so">
	    <updateRate>100.0</updateRate>
	    <leftFrontJoint>frontleft</leftFrontJoint>
	    <rightFrontJoint>frontright</rightFrontJoint>
	    <leftRearJoint>backleft</leftRearJoint>
	    <rightRearJoint>backright</rightRearJoint>
	    <wheelSeparation>0.20955</wheelSeparation>
	    <wheelDiameter>0.254</wheelDiameter>
	    <robotBaseFrame>base_link</robotBaseFrame>
	    <torque>75</torque> <!--can start rotating base at torque > & == 50-->
	    <topicName>cmd_vel</topicName>
	    <commandTopic>cmd_vel</commandTopic>
	    <odometryTopic>odom</odometryTopic>
	    <odometryFrame>odom</odometryFrame>
	    <publishOdom>true</publishOdom>
	    <broadcastTF>true</broadcastTF>
	    <covariance_x>0.0001</covariance_x>
	    <covariance_y>0.0001</covariance_y>
	    <covariance_yaw>0.01</covariance_yaw>
	  </plugin>
	</gazebo>

  <gazebo>
    <plugin name="gazebo_ros_control" filename="libgazebo_ros_control.so">
      <robotNamespace>rover_autonav</robotNamespace>
      <robotSimType>gazebo_ros_control/DefaultRobotHWSim</robotSimType>
    </plugin>
  </gazebo>

<!-- Rear wheels transmission -->

<transmission name="rear_left_wheel">
    <type>transmission_interface/SimpleTransmission</type>
    <joint name="backleft">
        <hardwareInterface>hardware_interface/EffortJointInterface</hardwareInterface>
    </joint>
    <actuator name="motor_rear_left_wheel">
        <hardwareInterface>hardware_interface/EffortJointInterface</hardwareInterface>
        <mechanicalReduction>1</mechanicalReduction>
    </actuator>
</transmission>

<transmission name="rear_right_wheel">
    <type>transmission_interface/SimpleTransmission</type>
    <joint name="backright">
        <hardwareInterface>hardware_interface/EffortJointInterface</hardwareInterface>
    </joint>
    <actuator name="motor_rear_right_wheel">
        <hardwareInterface>hardware_interface/EffortJointInterface</hardwareInterface>
        <mechanicalReduction>1</mechanicalReduction>
    </actuator>
</transmission>

<!-- Front wheels transmission -->

<transmission name="front_left_wheel">
    <type>transmission_interface/SimpleTransmission</type>
    <joint name="frontleft">
        <hardwareInterface>hardware_interface/EffortJointInterface</hardwareInterface>
    </joint>
    <actuator name="motor_front_left_wheel">
        <hardwareInterface>hardware_interface/EffortJointInterface</hardwareInterface>
        <mechanicalReduction>1</mechanicalReduction>
    </actuator>
</transmission>

<transmission name="front_right_wheel">
    <type>transmission_interface/SimpleTransmission</type>
    <joint name="frontright">
        <hardwareInterface>hardware_interface/EffortJointInterface</hardwareInterface>
    </joint>
    <actuator name="motor_front_right_wheel">
        <hardwareInterface>hardware_interface/EffortJointInterface</hardwareInterface>
        <mechanicalReduction>1</mechanicalReduction>
    </actuator>
</transmission>

</robot>
