<?xml version="1.0"?>
<robot name="scorbot" xmlns:xacro="http://wiki.ros.org/xacro">

  <xacro:property name="M_PI" value="3.1415926535897931" />
  <xacro:property name="d435_cam_width" value="0.09"/>
  <xacro:property name="d435_cam_depth" value="0.025"/>
  <xacro:property name="d435_cam_height" value="0.025"/>


  <xacro:macro name="scorbot" params="prefix parent *origin">
  
    <!-- Used for fixing robot to Gazebo 'base_link' -->
    <!-- <link name="world"/>

    <joint name="fixed" type="fixed">
      <parent link="world"/>
      <child link="base_link"/>
    </joint> -->

    <joint name="${prefix}_base_joint" type="fixed">
      <xacro:insert_block name="origin"/>
      <parent link="${parent}"/>
      <child link="${prefix}_base_link"/>
    </joint>

    <!--BASE LINK-->
    <link name="${prefix}_base_link">
      <inertial>
        <origin
          xyz="0.13275 0.14932 0.15353"
          rpy="0 0 0" />
        <mass
          value="13.939" />
        <inertia
          ixx="0.10125"
          ixy="-0.00021844"
          ixz="-0.00033793"
          iyy="0.087972"
          iyz="0.0034335"
          izz="0.095961" />
      </inertial>
      <visual>
        <geometry>
          <mesh filename="package://manipulation/scorbot_description/meshes/visual/Parte_1(1).DAE"/>
        </geometry>
      </visual>
      <collision>
        <origin xyz="0 0 0" rpy="0 0 0"/>
        <geometry>
          <mesh filename="package://manipulation/scorbot_description/meshes/visual/Parte_1(1).DAE"/>
        </geometry>
      </collision> 
    </link>
    <!--Link 1 SHOULDER LINK-->
    <link name="${prefix}_link_1">
      <inertial>
        <origin
          xyz="0.13275 0.14932 0.15353"
          rpy="0 0 0" />
        <mass
          value="0.01" />
        <inertia
          ixx="0.069345"
          ixy="0.00053463"
          ixz="-9.59E-05"
          iyy="0.09864"
          iyz="0.0061367"
          izz="0.10261" />
      </inertial>
      <visual>
        <geometry>
          <mesh filename="package://manipulation/scorbot_description/meshes/visual/Parte_2(1)x.DAE"/>
        </geometry>
      </visual> 
      <collision>
        <origin xyz="0 0 0" rpy="0 0 0"/>
        <geometry>
          <mesh filename="package://manipulation/scorbot_description/meshes/visual/Parte_2(1)x.DAE"/>
        </geometry>
      </collision>
    </link>

    <!--Joint 1 BASE JOINT-->
    <joint name="${prefix}_joint_1" type="revolute">
      <parent link="${prefix}_base_link"/>
      <child link="${prefix}_link_1"/>
      <origin xyz="0 0 0.2274" rpy="0 0 0"/>
      <axis xyz="0 0 1"/>
      <limit lower="-5.4105207" upper="5.4105207" effort="0" velocity="2"/>
    </joint>


    <!--Link 2 ELBOW LINK-->
    <link name="${prefix}_link_2">
      <inertial>
        <origin
          xyz="0.13275 0.14932 0.15353"
          rpy="0 0 0" />
        <mass
          value="0.001" />
        <inertia
          ixx="0.021626"
          ixy="-8.9392E-17"
          ixz="2.0553E-15"
          iyy="0.013632"
          iyz="-2.3367E-05"
          izz="0.033242" />
    </inertial>
      <visual>
        <geometry>
          <mesh filename="package://manipulation/scorbot_description/meshes/visual/Parte_3(2)x.DAE"/>
        </geometry>
      </visual> 
      <collision>
        <origin xyz="0 0 0" rpy="0 0 0"/>
        <geometry>
          <mesh filename="package://manipulation/scorbot_description/meshes/visual/Parte_3(2)x.DAE"/>
        </geometry>
      </collision>
    </link>

    <!--Joint 2 SHOULDER JOINT-->
    <joint name="${prefix}_joint_2" type="revolute">
      <parent link="${prefix}_link_1"/>
      <child link="${prefix}_link_2"/>
      <origin xyz="0.0255 0 0.13" rpy="-1.570796327 -1.570796327 0"/>
      <axis xyz="0 0 1"/>
      <limit lower="-0.610865" upper="2.268928" effort="0" velocity="2"/>
      <dynamics
        damping="0.0"
        friction="0.01" />
    </joint>

    <!--Link 3 PITCH LINK-->
    <link name="${prefix}_link_3">
      <inertial>
        <origin
          xyz="0.13275 0.14932 0.15353"
          rpy="0 0 0" />
        <mass
          value="0.001" />
        <inertia
          ixx="0.027436"
          ixy="-1.1652E-13"
          ixz="-1.6685E-15"
          iyy="0.0081405"
          iyz="0.00011392"
          izz="0.034105" />
    </inertial>
      <visual>
        <geometry>
          <mesh filename="package://manipulation/scorbot_description/meshes/visual/Parte_4x.DAE"/>
        </geometry>
      </visual> 
      <collision>
        <origin xyz="0 0 0" rpy="0 0 0"/>
        <geometry>
          <mesh filename="package://manipulation/scorbot_description/meshes/visual/Parte_4x.DAE"/>
        </geometry>
      </collision>
    </link>

    <!--Joint 3 ELBOW JOINT-->
    <joint name="${prefix}_joint_3" type="revolute">
      <parent link="${prefix}_link_2"/>
      <child link="${prefix}_link_3"/>
      <origin xyz="0.2225 0 0" rpy="0 0 0"/>
      <axis xyz="0 0 1"/>
      <limit lower="-2.268928" upper="2.268928" effort="0" velocity="2"/>
    </joint>

    <!--Link 4 ROLL LINK-->
    <link name="${prefix}_link_4">
      <inertial>
        <origin
          xyz="0.13275 0.14932 0.15353"
          rpy="0 0 0" />
        <mass
          value="0.001" />
        <inertia
          ixx="0.027436"
          ixy="-1.1652E-13"
          ixz="-1.6685E-15"
          iyy="0.0081405"
          iyz="0.00011392"
          izz="0.034105" />
    </inertial>
      <visual>
        <origin rpy="0 0 0" xyz="0.012 0 0"/>
        <geometry>
          <mesh filename="package://manipulation/scorbot_description/meshes/visual/Parte_6x.DAE"/>
        </geometry>
      </visual> 
      <collision>
        <origin xyz="0 0 0" rpy="0 0 0"/>
        <geometry>
          <mesh filename="package://manipulation/scorbot_description/meshes/visual/Parte_6x.DAE"/>
        </geometry>
      </collision>
    </link>

    <!--Joint 4 PITCH JOINT-->
    <joint name="${prefix}_joint_4" type="revolute">
      <parent link="${prefix}_link_3"/>
      <child link="${prefix}_link_4"/>
      <origin xyz="0.2225 0 0" rpy="0 0 0"/>
      <axis xyz="0 0 1"/>
      <limit lower="-2.268928" upper="2.268928" effort="0" velocity="2"/>
      <dynamics
        damping="0.01"
        friction="0.01" />
    </joint>

    <!--Link 5 GRIPPER LINK-->
    <link name="${prefix}_link_5">
      <inertial>
        <origin
          xyz="2.2204E-16 -8.3267E-17 0.070299"
          rpy="0 0 0" />
        <mass
          value="0.0001" />" />
        <inertia
          ixx="0.00098187"
          ixy="-2.7952E-20"
          ixz="2.8189E-18"
          iyy="0.00095638"
          iyz="-2.4183E-18"
          izz="0.00013429" />
      </inertial>
      <visual>
        <origin
          xyz="0 0 0"
          rpy="0 0 0" />
        <geometry>
          <mesh filename="package://manipulation/scorbot_description/meshes/gripper_Link.STL" />
        </geometry>
        <material
          name="">
          <color
          rgba="0.1 0.1 0.1 1" />
        </material>
      </visual> 
      <collision>
        <origin xyz="0 0 0" rpy="0 0 0"/>
        <geometry>
          <mesh filename="package://manipulation/scorbot_description/meshes/gripper_Link.STL" />
        </geometry>
      </collision>
    </link>

    <!--Joint 5 ROLL JOINT-->
    <joint name="${prefix}_joint_5" type="revolute">
      <parent link="${prefix}_link_4"/>
      <child link="${prefix}_link_5"/>
      <origin xyz="0 0 0" rpy="0.0 -1.570796327 0.0" />
      <axis xyz="0 0 1"/>
      <limit
        lower="-3.14159"
        upper="3.14159"
        effort="2"
        velocity="2" />
      <dynamics damping="0.01" friction="0.01" />
    </joint>


    <!--PAD1 LINK-->
    <link name="${prefix}_pad1_Link">
      <inertial>
        <origin
          xyz="-0.039374 5.5511E-17 -0.00025"
          rpy="0 0 0" />
        <mass
          value="0.0001" />
        <inertia
          ixx="0.00098187"
          ixy="-2.7952E-20"
          ixz="2.8189E-18"
          iyy="0.00095638"
          iyz="-2.4183E-18"
          izz="0.00013429" />
      </inertial>
      <visual>
        <origin
          xyz="0 0 0"
          rpy="0 0 0" />
        <geometry>
          <mesh
            filename="package://manipulation/scorbot_description/meshes/pad1_Link.STL" />
        </geometry>
        <material
          name="">
          <color
          rgba="0.1 0 0 1" />
        </material>
      </visual>
      <collision>
        <origin
          xyz="0 0 0"
          rpy="0 0 0" />
        <geometry>
          <mesh
            filename="package://manipulation/scorbot_description/meshes/pad1_Link.STL" />
        </geometry>
      </collision>
    </link>

    <!--PAD1 JOINT-->
    <joint  name="${prefix}_pad1_joint" type="revolute">
      <origin xyz="0 -0.0545 -0.0905" rpy="1.5708 -0.74758 -1.5708" />
      <parent link="${prefix}_link_5" />
      <child link="${prefix}_pad1_Link" />
      <axis xyz="0 0 1" />
      <limit
        lower="0"
        upper="1.5709"
        effort="1"
        velocity="2" />
      <dynamics damping="0.01" friction="0.01" />
    </joint>

    <!--PAD2 LINK-->
    <link name="${prefix}_pad2_Link">
      <inertial>
        <origin
          xyz="-0.039374 -2.2204E-16 -0.00025"
          rpy="0 0 0" />
        <mass
          value="0.0001" />
        <inertia
          ixx="0.00098187"
          ixy="-2.7952E-20"
          ixz="2.8189E-18"
          iyy="0.00095638"
          iyz="-2.4183E-18"
          izz="0.00013429" />
      </inertial>
      <visual>
        <origin
          xyz="0 0 0"
          rpy="0 0 0" />
        <geometry>
          <mesh
            filename="package://manipulation/scorbot_description/meshes/pad2_Link.STL" />
        </geometry>
        <material
          name="">
          <color
          rgba="0.1 0 0 1" />
        </material>
      </visual>
      <collision>
        <origin
          xyz="0 0 0"
          rpy="0 0 0" />
        <geometry>
          <mesh
            filename="package://manipulation/scorbot_description/meshes/pad2_Link.STL" />
        </geometry>
      </collision>
    </link>
    <!--PAD2 JOINT-->
    <joint name="${prefix}_pad2_joint" type="revolute">
      <origin xyz="0 0.0545 -0.0905" rpy="-1.5708 -0.74758 1.5708" />
      <parent link="${prefix}_link_5" />
      <child link="${prefix}_pad2_Link" />
      <axis xyz="0 0 -1" />
      <limit
        lower="0"
        upper="1.5709"
        effort="1"
        velocity="2" />
      <dynamics damping="0.01" friction="0.01" />
      <mimic joint="${prefix}_pad1_joint" multiplier="1.0" offset="0"/> 
    </joint>   

    <!-- Camera -->
    <link name="camera_link">
      <inertial>
        <mass value="0.001"/>
        <origin xyz="0.0 0.0 0.0" rpy="0 0 0"/>
        <inertia
          ixx="1e-6" ixy="0.0" ixz="0.0"
          iyy="1e-6" iyz="0.0"
          izz="1e-6"
          />
      </inertial>
      <visual>
        <origin xyz="0 0 0" rpy="0 0 0"/>
        <geometry>
          <!-- <box size="${d435_cam_width} ${d435_cam_depth} ${d435_cam_height}"/> -->
          <mesh filename="package://rover_autonav/meshes/d435.dae"/>
        </geometry>
      </visual>
      <collision>
        <origin xyz="0 0 0" rpy="0 0 0"/>
        <geometry>
          <box size="${d435_cam_width} ${d435_cam_depth} ${d435_cam_height}"/>
        </geometry>
      </collision>
    </link>

    <!-- Camera Joint -->
    <joint name="camera_joint" type="fixed">
      <origin xyz="0.0 -0.07 0.0" rpy="${M_PI} 0 0" />
      <parent link="${prefix}_link_5"/>
      <child link="camera_link" />
    </joint>
    
    <!-- camera depth joints and links -->
    <!-- <joint name="camera_depth_joint" type="fixed">
      <origin xyz="${r430_cam_depth_px} ${r430_cam_depth_py} ${r430_cam_depth_pz}" rpy="0 0 0"/>
      <parent link="camera_link"/>
      <child link="camera_depth_frame" />
    </joint>

    <link name="camera_depth_frame"/> -->


    <!-- Camera oriented -->
    <joint name="camera_link_oriented_joint" type="fixed">
      <origin xyz="0 0 0" rpy="0 ${-M_PI/2} ${-M_PI/2}" />
      <parent link="camera_link" />
      <child link="camera_link_oriented" />
    </joint>

    <link name="camera_link_oriented"/>


    <!-- Camera Depth Optical Frame -->
    <joint name="camera_depth_optical_frame_joint" type="fixed">
      <origin xyz="0 -0.0115 0" rpy="${-M_PI/2} 0 ${-M_PI/2}" />
      <parent link="camera_link_oriented" />
      <child link="camera_depth_optical_frame" />
    </joint>

    <link name="camera_depth_optical_frame"/>


    <!-- Camera plugin -->
    <gazebo reference="camera_link_oriented">
      <sensor type="depth" name="camera_depth_sensor">
        <always_on>true</always_on>
        <update_rate>15.0</update_rate>
        <camera>
          <horizontal_fov>${91.2*M_PI/180.0}</horizontal_fov>
          <image>
            <format>R8G8B8</format>
            <width>640</width>
            <height>480</height>
          </image>
          <clip>
            <near>0.3</near>
            <far>5.0</far>
          </clip>
        </camera>
        <plugin name="camera_plugin" filename="libgazebo_ros_openni_kinect.so">
          <cameraName>front_rgbd_camera</cameraName>
          <alwaysOn>true</alwaysOn>
          <updateRate>10</updateRate>
          <imageTopicName>rgb/image_raw</imageTopicName>
          <depthImageTopicName>depth/image_raw</depthImageTopicName>
          <pointCloudTopicName>depth/points</pointCloudTopicName>
          <cameraInfoTopicName>rgb/camera_info</cameraInfoTopicName>
          <depthImageCameraInfoTopicName>depth/camera_info</depthImageCameraInfoTopicName>
          <frameName>camera_depth_optical_frame</frameName>
          <baseline>0.1</baseline>
          <distortion_k1>0.0</distortion_k1>
          <distortion_k2>0.0</distortion_k2>
          <distortion_k3>0.0</distortion_k3>
          <distortion_t1>0.0</distortion_t1>
          <distortion_t2>0.0</distortion_t2>
          <pointCloudCutoff>0.1</pointCloudCutoff>
        </plugin>
      </sensor>
    </gazebo>


    <!--Transmission Base -->
    <transmission name="baseTransmission">
      <type>transmission_interface/SimpleTransmission</type>
      <joint name="${prefix}_joint_1" type="SimpleTransmission">
        <hardwareInterface>hardware_interface/PositionJointInterface</hardwareInterface>
      </joint>
      <actuator name="base_motor">
        <machanicalReduction>1</machanicalReduction>
        <hardwareInterface>hardware_interface/PositionJointInterface</hardwareInterface>
      </actuator>
    </transmission>

    <!--Transmission Shoulder-->
    <transmission name="shoulderTransmission">
      <type>transmission_interface/SimpleTransmission</type>
      <joint name="${prefix}_joint_2" type="SimpleTransmission">
        <hardwareInterface>hardware_interface/PositionJointInterface</hardwareInterface>
      </joint>
      <actuator name="shoulder_motor">
        <machanicalReduction>1</machanicalReduction>
        <hardwareInterface>hardware_interface/PositionJointInterface</hardwareInterface>
      </actuator>
    </transmission>

    <!--Transmission Elbow-->
    <transmission name="elbowTransmission">
      <type>transmission_interface/SimpleTransmission</type>
      <joint name="${prefix}_joint_3" type="SimpleTransmission">
        <hardwareInterface>hardware_interface/PositionJointInterface</hardwareInterface>
      </joint>
      <actuator name="elbow_motor">
        <machanicalReduction>1</machanicalReduction>
        <hardwareInterface>hardware_interface/PositionJointInterface</hardwareInterface>
      </actuator>
    </transmission>

    <!--Transmission Pitch-->
    <transmission name="pitchTransmission">
      <type>transmission_interface/SimpleTransmission</type>
      <joint name="${prefix}_joint_4" type="SimpleTransmission">
        <hardwareInterface>hardware_interface/PositionJointInterface</hardwareInterface>
      </joint>
      <actuator name="pitch_motor">
        <machanicalReduction>1</machanicalReduction>
        <hardwareInterface>hardware_interface/PositionJointInterface</hardwareInterface>
      </actuator>
    </transmission>

    <!--Transmission Roll-->
    <transmission name="pitchTransmission">
      <type>transmission_interface/SimpleTransmission</type>
      <joint name="${prefix}_joint_5" type="SimpleTransmission">
        <hardwareInterface>hardware_interface/PositionJointInterface</hardwareInterface>
      </joint>
      <actuator name="pitch_motor">
        <machanicalReduction>1</machanicalReduction>
        <hardwareInterface>hardware_interface/PositionJointInterface</hardwareInterface>
      </actuator>
    </transmission>

    <!-- Transmission pad1-->

    <transmission name="pad1Transmission">
      <type>transmission_interface/SimpleTransmission</type>
      <joint name="${prefix}_pad1_joint" >
        <hardwareInterface>hardware_interface/PositionJointInterface</hardwareInterface>
      </joint>
      <actuator name="pad1_motor">
        <mechanicalReduction>1</mechanicalReduction>
        <hardwareInterface>hardware_interface/PositionJointInterface</hardwareInterface>
      </actuator>
    </transmission>

    <!-- Gazebo plugin for ROS Control -->
    <gazebo>
      <plugin name="gazebo_ros_control" filename="libgazebo_ros_control.so">
          <!-- <robotNamespace>/scorbot</robotNamespace> -->
      </plugin>
    </gazebo>

    <!-- Gazebo plugin MIMIC JOINT-->
    <gazebo>
      <plugin name="mimic_pad1_joint" filename="libroboticsgroup_gazebo_mimic_joint_plugin.so">
        <joint>${prefix}_pad1_joint</joint>
        <mimicJoint>${prefix}_pad2_joint</mimicJoint>
        <hasPID />
        <multiplier>1.0</multiplier>
        <offset>0</offset>
        <sensitiveness>0.0</sensitiveness>   
        <maxEffort>10.0</maxEffort>                       
          <!-- <robotNamespace>/scorbot</robotNamespace> -->
      </plugin>
    </gazebo>

    <!-- Gazebo plugin Grasp-->
    <gazebo>
      <plugin name="gazebo_grasp_fix" filename="libgazebo_grasp_fix.so">
        <arm>
            <arm_name>ur_manipulator</arm_name>
            <palm_link>${prefix}_link_5</palm_link>
            <gripper_link>${prefix}_pad1_Link</gripper_link>
            <gripper_link>${prefix}_pad2_Link</gripper_link>
        </arm>
        <forces_angle_tolerance>90</forces_angle_tolerance>
        <update_rate>10</update_rate>
        <grip_count_threshold>1</grip_count_threshold>
        <max_grip_count>20</max_grip_count>
        <release_tolerance>0.03</release_tolerance>
        <disable_collisions_on_attach>true</disable_collisions_on_attach>
        <contact_topic>__default_topic__</contact_topic>
      </plugin>
    </gazebo>
    


  </xacro:macro>

</robot>
